Workbook
Name Slicer_Category: #N/A
Name Slicer_Months__Order_Date: #N/A
Name Slicer_Store_City: #N/A
Name Slicer_Years__Order_Date: #N/A

Sheet Sheet1

Sheet Pivot
B2: PRIMARY KPIs
B3: Sum of Sales | C3: Sum of Profit | D3: Count of Order_ID
B4: 1953720 | C4: 457620 | D4: 60
B8: Monthly Revenue, Profit and Expenses
B9: Row Labels | C9: Sum of Sales | D9: Sum of Profit | E9: Sum of Cost | I9: Row Labels | J9: Sum of Sales | K9: Sum of Profit | L9: Sum of Cost
B10: Sep | C10: 1953720 | D10: 457620 | E10: 1496100 | I10: Jan | J10: 1605289 | K10: 382389 | L10: 1222900
B11: Grand Total | C11: 1953720 | D11: 457620 | E11: 1496100 | I11: Feb | J11: 958032 | K11: 225782 | L11: 732250
I12: Mar | J12: 1452570 | K12: 343070 | L12: 1109500
I13: Apr | J13: 1432076 | K13: 334026 | L13: 1098050
I14: May | J14: 922420 | K14: 215120 | L14: 707300
I15: Jun | J15: 646490 | K15: 151590 | L15: 494900
I16: Jul | J16: 643343 | K16: 151193 | L16: 492150
I17: Aug | J17: 913806 | K17: 214506 | L17: 699300
I18: Sep | J18: 1953720 | K18: 457620 | L18: 1496100
I19: Oct | J19: 920215 | K19: 216315 | L19: 703900
I20: Nov | J20: 1563188 | K20: 364088 | L20: 1199100
I21: Dec | J21: 1211502 | K21: 283302 | L21: 928200
I22: Grand Total | J22: 14222651 | K22: 3339001 | L22: 10883650
B24: Category Sales, Profit Distribution
B25: Row Labels | C25: Sum of Sales | D25: Sum of Profit | E25: Count of Order_ID | I25: Row Labels | J25: Sum of Sales | K25: Sum of Profit | L25: Count of Order_ID
B26: Clothing | C26: 162260 | D26: 39260 | E26: 6 | I26: Clothing | J26: 162260 | K26: 39260 | L26: 6
B27: Grand Total | C27: 162260 | D27: 39260 | E27: 6 | I27: Electronics | J27: 631520 | K27: 148120 | L27: 15
I28: Furniture | J28: 914555 | K28: 210155 | L28: 26
I29: Other | J29: 166455 | K29: 40455 | L29: 7
I30: Sports | J30: 78930 | K30: 19630 | L30: 6
I31: Grand Total | J31: 1953720 | K31: 457620 | L31: 60
B34: City by Sales
B35: Row Labels | C35: Sum of Sales | I35: Row Labels | J35: Sum of Sales
B36: Los Angeles | C36: 171460 | I36: Chicago | J36: 367970
B37: Grand Total | C37: 171460 | I37: Houston | J37: 1140290
I38: Los Angeles | J38: 171460
I39: New York | J39: 274000
I40: Grand Total | J40: 1953720
B43: Payment Sales Distribution
B44: Row Labels | C44: Sum of Sales
B45: Card | C45: 981600
B46: Cash | C46: 339110
B47: Online | C47: 633010
B48: Grand Total | C48: 1953720
B51: Store-Region by Sales
...

Sheet Processing
A1: Total Sales | B1: Total Profit | C1: Total Orders | D1: Profit Margin %
A2: =GETPIVOTDATA("Sum of Sales",Pivot!$B$3) -> 1953720 | B2: =GETPIVOTDATA("Sum of Profit",Pivot!$B$3) -> 457620 | C2: =GETPIVOTDATA("Count of Order_ID",Pivot!$B$3) -> 60 | D2: =B2/A2 -> 0.23423008
E4: =MAX(B6:B17)*5% -> 97686
A5: Monthly Revenue vs Costs | B5: Revenue | C5: Cost | D5: Cursor R | E5: Indent | F5: indent3
A6: Jan | B6: =GETPIVOTDATA("Sum of Sales",Pivot!$I$9,"Months (Order_Date)",A6) -> 1605289 | C6: =GETPIVOTDATA("Sum of Cost",Pivot!$I$9,"Months (Order_Date)",A6) -> 1222900 | D6: =IFERROR(GETPIVOTDATA("Sum of Sales",Pivot!$B$9,"Months (Order_Date)",A6),NA()) -> #N/A | E6: =$E$4 -> 97686 | F6: =IF(ISNUMBER(D6),E6,NA()) -> #N/A
A7: Feb | B7: =GETPIVOTDATA("Sum of Sales",Pivot!$I$9,"Months (Order_Date)",A7) -> 958032 | C7: =GETPIVOTDATA("Sum of Cost",Pivot!$I$9,"Months (Order_Date)",A7) -> 732250 | D7: =IFERROR(GETPIVOTDATA("Sum of Sales",Pivot!$B$9,"Months (Order_Date)",A7),NA()) -> #N/A | E7: =$E$4 -> 97686 | F7: =IF(ISNUMBER(D7),E7,NA()) -> #N/A
A8: Mar | B8: =GETPIVOTDATA("Sum of Sales",Pivot!$I$9,"Months (Order_Date)",A8) -> 1452570 | C8: =GETPIVOTDATA("Sum of Cost",Pivot!$I$9,"Months (Order_Date)",A8) -> 1109500 | D8: =IFERROR(GETPIVOTDATA("Sum of Sales",Pivot!$B$9,"Months (Order_Date)",A8),NA()) -> #N/A | E8: =$E$4 -> 97686 | F8: =IF(ISNUMBER(D8),E8,NA()) -> #N/A
A9: Apr | B9: =GETPIVOTDATA("Sum of Sales",Pivot!$I$9,"Months (Order_Date)",A9) -> 1432076 | C9: =GETPIVOTDATA("Sum of Cost",Pivot!$I$9,"Months (Order_Date)",A9) -> 1098050 | D9: =IFERROR(GETPIVOTDATA("Sum of Sales",Pivot!$B$9,"Months (Order_Date)",A9),NA()) -> #N/A | E9: =$E$4 -> 97686 | F9: =IF(ISNUMBER(D9),E9,NA()) -> #N/A
A10: May | B10: =GETPIVOTDATA("Sum of Sales",Pivot!$I$9,"Months (Order_Date)",A10) -> 922420 | C10: =GETPIVOTDATA("Sum of Cost",Pivot!$I$9,"Months (Order_Date)",A10) -> 707300 | D10: =IFERROR(GETPIVOTDATA("Sum of Sales",Pivot!$B$9,"Months (Order_Date)",A10),NA()) -> #N/A | E10: =$E$4 -> 97686 | F10: =IF(ISNUMBER(D10),E10,NA()) -> #N/A
A11: Jun | B11: =GETPIVOTDATA("Sum of Sales",Pivot!$I$9,"Months (Order_Date)",A11) -> 646490 | C11: =GETPIVOTDATA("Sum of Cost",Pivot!$I$9,"Months (Order_Date)",A11) -> 494900 | D11: =IFERROR(GETPIVOTDATA("Sum of Sales",Pivot!$B$9,"Months (Order_Date)",A11),NA()) -> #N/A | E11: =$E$4 -> 97686 | F11: =IF(ISNUMBER(D11),E11,NA()) -> #N/A
A12: Jul | B12: =GETPIVOTDATA("Sum of Sales",Pivot!$I$9,"Months (Order_Date)",A12) -> 643343 | C12: =GETPIVOTDATA("Sum of Cost",Pivot!$I$9,"Months (Order_Date)",A12) -> 492150 | D12: =IFERROR(GETPIVOTDATA("Sum of Sales",Pivot!$B$9,"Months (Order_Date)",A12),NA()) -> #N/A | E12: =$E$4 -> 97686 | F12: =IF(ISNUMBER(D12),E12,NA()) -> #N/A
A13: Aug | B13: =GETPIVOTDATA("Sum of Sales",Pivot!$I$9,"Months (Order_Date)",A13) -> 913806 | C13: =GETPIVOTDATA("Sum of Cost",Pivot!$I$9,"Months (Order_Date)",A13) -> 699300 | D13: =IFERROR(GETPIVOTDATA("Sum of Sales",Pivot!$B$9,"Months (Order_Date)",A13),NA()) -> #N/A | E13: =$E$4 -> 97686 | F13: =IF(ISNUMBER(D13),E13,NA()) -> #N/A
A14: Sep | B14: =GETPIVOTDATA("Sum of Sales",Pivot!$I$9,"Months (Order_Date)",A14) -> 1953720 | C14: =GETPIVOTDATA("Sum of Cost",Pivot!$I$9,"Months (Order_Date)",A14) -> 1496100 | D14: =IFERROR(GETPIVOTDATA("Sum of Sales",Pivot!$B$9,"Months (Order_Date)",A14),NA()) -> 1953720 | E14: =$E$4 -> 97686 | F14: =IF(ISNUMBER(D14),E14,NA()) -> 97686
A15: Oct | B15: =GETPIVOTDATA("Sum of Sales",Pivot!$I$9,"Months (Order_Date)",A15) -> 920215 | C15: =GETPIVOTDATA("Sum of Cost",Pivot!$I$9,"Months (Order_Date)",A15) -> 703900 | D15: =IFERROR(GETPIVOTDATA("Sum of Sales",Pivot!$B$9,"Months (Order_Date)",A15),NA()) -> #N/A | E15: =$E$4 -> 97686 | F15: =IF(ISNUMBER(D15),E15,NA()) -> #N/A
A16: Nov | B16: =GETPIVOTDATA("Sum of Sales",Pivot!$I$9,"Months (Order_Date)",A16) -> 1563188 | C16: =GETPIVOTDATA("Sum of Cost",Pivot!$I$9,"Months (Order_Date)",A16) -> 1199100 | D16: =IFERROR(GETPIVOTDATA("Sum of Sales",Pivot!$B$9,"Months (Order_Date)",A16),NA()) -> #N/A | E16: =$E$4 -> 97686 | F16: =IF(ISNUMBER(D16),E16,NA()) -> #N/A
A17: Dec | B17: =GETPIVOTDATA("Sum of Sales",Pivot!$I$9,"Months (Order_Date)",A17) -> 1211502 | C17: =GETPIVOTDATA("Sum of Cost",Pivot!$I$9,"Months (Order_Date)",A17) -> 928200 | D17: =IFERROR(GETPIVOTDATA("Sum of Sales",Pivot!$B$9,"Months (Order_Date)",A17),NA()) -> #N/A | E17: =$E$4 -> 97686 | F17: =IF(ISNUMBER(D17),E17,NA()) -> #N/A
A18: Cost % | B18: Total Revenue | C18: Total Cost
A19: =C19/B19 -> 0.76576992 | B19: =SUMIF(D6:D17,">0") -> 1953720 | C19: =SUMIF(D6:D17,">0",C6:C17) -> 1496100
A21: Category by Revenue | B21: Other | C21: Sports | D21: Clothing | E21: Furniture | F21: Electronics
A22: Value | B22: =GETPIVOTDATA("Sum of Sales",Pivot!$I$25,"Category",B21) -> 166455 | C22: =GETPIVOTDATA("Sum of Sales",Pivot!$I$25,"Category",C21) -> 78930 | D22: =GETPIVOTDATA("Sum of Sales",Pivot!$I$25,"Category",D21) -> 162260 | E22: =GETPIVOTDATA("Sum of Sales",Pivot!$I$25,"Category",E21) -> 914555 | F22: =GETPIVOTDATA("Sum of Sales",Pivot!$I$25,"Category",F21) -> 631520
A23: % | B23: =B22/$B$24 -> 0.085199005 | C23: =C22/$B$24 -> 0.040399853 | D23: =D22/$B$24 -> 0.083051819 | E23: =E22/$B$24 -> 0.46810956 | F23: =F22/$B$24 -> 0.32323977
A24: Total | B24: =SUM(B22:F22) -> 1953720
B29: Electronics | D29: Furniture | F29: Clothing | H29: Sports | J29: Other | K29: Sectors
A30: Done | B30: {=(100%-B32)*INDEX($B$23:$G$23,1,B33)} -> 0.063899254 | C30: {=(100%-C32)*INDEX($B$23:$G$23,1,C33)} -> 0.063899254 | D30: {=(100%-D32)*INDEX($B$23:$G$23,1,D33)} -> 0.030299889 | E30: {=(100%-E32)*INDEX($B$23:$G$23,1,E33)} -> 0.030299889 | F30: {=(100%-F32)*INDEX($B$23:$G$23,1,F33)} -> 0.062288864 | G30: {=(100%-G32)*INDEX($B$23:$G$23,1,G33)} -> 0.062288864 | H30: {=(100%-H32)*INDEX($B$23:$G$23,1,H33)} -> 0.35108217 | I30: {=(100%-I32)*INDEX($B$23:$G$23,1,I33)} -> 0.35108217 | J30: {=(100%-J32)*INDEX($B$23:$G$23,1,J33)} -> 0.24242983 | K30: 0.75
A31: Running | B31: =100%-B30-B32 -> 0.68610075 | C31: =100%-C30-C32 -> 0.68610075 | D31: =100%-D30-D32 -> 0.71970011 | E31: =100%-E30-E32 -> 0.71970011 | F31: =100%-F30-F32 -> 0.68771114 | G31: =100%-G30-G32 -> 0.68771114 | H31: =100%-H30-H32 -> 0.39891783 | I31: =100%-I30-I32 -> 0.39891783 | J31: =100%-J30-J32 -> 0.50757017 | K31: 0
B32: =$K$32 -> 0.25 | C32: =$K$32 -> 0.25 | D32: =$K$32 -> 0.25 | E32: =$K$32 -> 0.25 | F32: =$K$32 -> 0.25 | G32: =$K$32 -> 0.25 | H32: =$K$32 -> 0.25 | I32: =$K$32 -> 0.25 | J32: =$K$32 -> 0.25 | K32: =100%-K30 -> 0.25
B33: 1 | C33: 1 | D33: 2 | E33: 2 | F33: 3 | G33: 3 | H33: 4 | I33: 4 | J33: 5
H35: =MATCH(Pivot!B36,Processing!E37:E40,0) -> 3
A36: Store City by Sales | B36: Sales | C36: Cursor S | H36: =SUM(OFFSET(G36,0,0,H35,1)) -> 1508260
A37: Chicago | B37: =GETPIVOTDATA("Sales",Pivot!$I$35,"Store_City",A37) -> 367970 | C37: =IFERROR(GETPIVOTDATA("Sales",Pivot!$B$35,"Store_City",A37),NA()) -> #N/A | E37: Chicago | F37: =B37 -> 367970 | G37: =F37 -> 367970 | H37: =IF($H$35=1,G37,0) -> 0
A38: Houston | B38: =GETPIVOTDATA("Sales",Pivot!$I$35,"Store_City",A38) -> 1140290 | C38: =IFERROR(GETPIVOTDATA("Sales",Pivot!$B$35,"Store_City",A38),NA()) -> #N/A | E38: Houston | F38: =B38 -> 1140290 | G38: =F38 -> 1140290 | H38: =IF($H$35=2,G38,0) -> 0
A39: Los Angeles | B39: =GETPIVOTDATA("Sales",Pivot!$I$35,"Store_City",A39) -> 171460 | C39: =IFERROR(GETPIVOTDATA("Sales",Pivot!$B$35,"Store_City",A39),NA()) -> 171460 | E39: Los Angeles | F39: =B39 -> 171460 | G39: =F39 -> 171460 | H39: =IF($H$35=3,G39,0) -> 171460
A40: New York | B40: =GETPIVOTDATA("Sales",Pivot!$I$35,"Store_City",A40) -> 274000 | C40: =IFERROR(GETPIVOTDATA("Sales",Pivot!$B$35,"Store_City",A40),NA()) -> #N/A | E40: New York | F40: =B40 -> 274000 | G40: =F40 -> 274000 | H40: =IF($H$35=4,G40,0) -> 0
C41: =SUMIF(C37:C40,">0") -> 171460 | E41: Label | F41: {=INDEX(E37:E40,H35)} -> Los Angeles | G41: {=INDEX(F37:F40,H35)} -> 171460 | H41: =SUM(G37:G40)-SUM(H36:H40) -> 274000
F44: =MAX(E46:E48)*3% -> 29448
A45: Sales by Payment Method | B45: Sales | D45: Sales by Payment Method | E45: Sales | F45: Indent
A46: Card | B46: =GETPIVOTDATA("Sales",Pivot!$B$44,"Payment_Method",A46) -> 981600 | D46: {=_xlfn._xlws.SORT(A46:B48,2)} -> Cash | E46: 339110 | F46: =$F$44 -> 29448
A47: Cash | B47: =GETPIVOTDATA("Sales",Pivot!$B$44,"Payment_Method",A47) -> 339110 | D47: Online | E47: 633010 | F47: =$F$44 -> 29448
A48: Online | B48: =GETPIVOTDATA("Sales",Pivot!$B$44,"Payment_Method",A48) -> 633010 | D48: Card | E48: 981600 | F48: =$F$44 -> 29448
A51: Region by Sales | B51: Sales | D51: Region by Sales | E51: Sales | I51: %
...

Sheet Dashboard

Sheet Profit

Sheet Insights

Sheet Dataset
C2: All Records
B5: Order_ID | C5: Order_Date | D5: Store_ID | E5: Store_City | F5: Store_Region | G5: Product_ID | H5: Product_Name | I5: Category | J5: Sub_Category | K5: Customer_ID | L5: Customer_Name | M5: Segment | N5: Salesperson | O5: Quantity | P5: Unit_Price | Q5: Discount | R5: Sales | S5: Cost | T5: Profit | U5: Payment_Method
B6: ORD001 | C6: 45296 | D6: ST001 | E6: New York | F6: West | G6: PRD101 | H6: Samsung Galaxy S23 | I6: Electronics | J6: Smartphones | K6: CUST1001 | L6: Rajesh Kumar | M6: Consumer | N6: John Smith | O6: 2 | P6: 75000 | Q6: 5 | R6: 142500 | S6: 120000 | T6: 22500 | U6: Card
B7: ORD002 | C7: 45296 | D7: ST001 | E7: New York | F7: West | G7: PRD102 | H7: Sony Headphones | I7: Electronics | J7: Accessories | K7: CUST1002 | L7: Priya Patel | M7: Consumer | N7: John Smith | O7: 3 | P7: 3500 | Q7: 0 | R7: 10500 | S7: 7000 | T7: 3500 | U7: Cash
B8: ORD003 | C8: 45296 | D8: ST002 | E8: Los Angeles | F8: North | G8: PRD201 | H8: Levis Jeans | I8: Clothing | J8: Men's Wear | K8: CUST1003 | L8: Amit Singh | M8: Consumer | N8: Emily Johnson | O8: 4 | P8: 2500 | Q8: 10 | R8: 9000 | S8: 6000 | T8: 3000 | U8: Card
B9: ORD004 | C9: 45296 | D9: ST002 | E9: Los Angeles | F9: North | G9: PRD202 | H9: Nike Shoes | I9: Clothing | J9: Footwear | K9: CUST1004 | L9: Sunita Sharma | M9: Corporate | N9: Emily Johnson | O9: 2 | P9: 6000 | Q9: 5 | R9: 11400 | S9: 8000 | T9: 3400 | U9: Online
B10: ORD005 | C10: 45296 | D10: ST003 | E10: Chicago | F10: South | G10: PRD301 | H10: Dell Laptop | I10: Electronics | J10: Computers | K10: CUST1005 | L10: Vikram Reddy | M10: Corporate | N10: Michael Brown | O10: 1 | P10: 65000 | Q10: 8 | R10: 59800 | S10: 52000 | T10: 7800 | U10: Card
B11: ORD006 | C11: 45296 | D11: ST003 | E11: Chicago | F11: South | G11: PRD302 | H11: HP Printer | I11: Electronics | J11: Peripherals | K11: CUST1006 | L11: Anjali Nair | M11: Home Office | N11: Michael Brown | O11: 1 | P11: 15000 | Q11: 0 | R11: 15000 | S11: 11000 | T11: 4000 | U11: Online
B12: ORD007 | C12: 45296 | D12: ST004 | E12: Houston | F12: East | G12: PRD401 | H12: Wooden Table | I12: Furniture | J12: Tables | K12: CUST1007 | L12: Sushil Das | M12: Consumer | N12: Jessica Davis | O12: 1 | P12: 12000 | Q12: 10 | R12: 10800 | S12: 8000 | T12: 2800 | U12: Cash
B13: ORD008 | C13: 45296 | D13: ST004 | E13: Houston | F13: East | G13: PRD402 | H13: Office Chair | I13: Furniture | J13: Chairs | K13: CUST1008 | L13: Meera Roy | M13: Corporate | N13: Jessica Davis | O13: 3 | P13: 8000 | Q13: 5 | R13: 22800 | S13: 16000 | T13: 6800 | U13: Card
B14: ORD009 | C14: 45296 | D14: ST005 | E14: Houston | F14: South | G14: PRD501 | H14: Organic Dal | I14: Furniture | J14: Pulses | K14: CUST1009 | L14: Karthik Raja | M14: Consumer | N14: David Wilson | O14: 5 | P14: 120 | Q14: 0 | R14: 600 | S14: 400 | T14: 200 | U14: Cash
B15: ORD010 | C15: 45296 | D15: ST005 | E15: Houston | F15: South | G15: PRD502 | H15: Basmati Rice | I15: Furniture | J15: Grains | K15: CUST1010 | L15: Lakshmi Iyer | M15: Consumer | N15: David Wilson | O15: 10 | P15: 150 | Q15: 0 | R15: 1500 | S15: 1000 | T15: 500 | U15: Card
B16: ORD011 | C16: 45297 | D16: ST001 | E16: New York | F16: West | G16: PRD103 | H16: iPhone 15 | I16: Electronics | J16: Smartphones | K16: CUST1011 | L16: Ajay Desai | M16: Corporate | N16: John Smith | O16: 3 | P16: 85000 | Q16: 5 | R16: 242250 | S16: 200000 | T16: 42250 | U16: Card
B17: ORD012 | C17: 45297 | D17: ST001 | E17: New York | F17: West | G17: PRD104 | H17: Samsung TV | I17: Electronics | J17: Televisions | K17: CUST1012 | L17: Neha Shah | M17: Consumer | N17: John Smith | O17: 1 | P17: 55000 | Q17: 8 | R17: 50600 | S17: 42000 | T17: 8600 | U17: Online
... B1460: ORD1407 | C1460: 46015 | D1460: ST001 | E1460: New York | F1460: West | G1460: PRD331 | H1460: Merry Christmas Sale | I1460: Electronics | J1460: Festive | K1460: CUST2481 | L1460: Christmas Day CCCC1 | M1460: Consumer | N1460: John Smith | O1460: 3 | P1460: 22000 | Q1460: 15 | R1460: 56100 | S1460: 43000 | T1460: 13100 | U1460: Card
